<?xml version="1.0" ?>
<!-- =================================================================================== -->
<!-- |    This document was autogenerated by xacro from bur.urdf.xacro                 | -->
<!-- |    EDITING THIS FILE BY HAND IS NOT RECOMMENDED                                 | -->
<!-- =================================================================================== -->
<robot name="bur">
  <link name="bur/dlink"/>
  <joint name="bur/dummy_link" type="fixed">
    <origin rpy="0 0 0" xyz="0 0 0"/>
    <parent link="bur/dlink"/>
    <child link="bur/base_link"/>
  </joint>
  <link name="bur/base_link">
    <inertial>
      <mass value="14.8"/>
      <origin xyz="0 0 -0.12514963738441306"/>
      <!-- BlueROV2 values from "Model Predictive Control for the BlueROV2",
           Emil Már Einarsson, Andris Lipenitis, Master thesis, 2020
           for now make Ignition crash?-->
      <!--         <inertia ixx="0.21" ixy="0.00" ixz="0.00" iyy="0.245" iyz="0.00" izz="0.245"/> -->
      <inertia ixx="5.2539" ixy="0.0144" ixz="0.3341" iyy="7.9420" iyz="0.026" izz="6.9123"/>
      <!-- Perfect rectangle -->
      <!--        <inertia
           ixx="${mass/12*(y_size*y_size+z_size*z_size)}" ixy="0.0" ixz="0.0"
           iyy="${mass/12*(x_size*x_size + z_size*z_size)}" iyz="0.0"
           izz="${mass/12*(x_size*x_size + y_size*y_size)}" />-->
    </inertial>
    <visual>
      <geometry>
        <box size="0.25029927476882613 0.5005985495376523 0.12514963738441306"/>
      </geometry>
      <material name="grey"/>
    </visual>
    <collision>
      <origin xyz="0 0 -0.031287409346103266"/>
      <!-- Box adjusted for buoyancy -->
      <geometry>
        <box size="0.25029927476882613 0.5005985495376523 0.12514963738441306"/>
      </geometry>
    </collision>
    <!--    <gazebo>
         <velocity_decay>
         <linear>-250.15 -70.364 -170.955</linear>
         <angular>1.888 0.761 3.744</angular>
         </velocity_decay>
         </gazebo>-->
  </link>
  <!-- Colors -->
  <material name="yellow">
    <color rgba="0.92 0.83 0.0 1"/>
  </material>
  <material name="black">
    <color rgba="0.1 0.1 0.1 1"/>
  </material>
  <material name="grey">
    <color rgba="0.6 0.6 0.6 1"/>
  </material>
  <material name="red">
    <color rgba="0.93 0.14 0.14 1"/>
  </material>
  <gazebo>
    <plugin filename="ignition-gazebo-hydrodynamics-system" name="ignition::gazebo::systems::Hydrodynamics">
      <link_name>bur/dlink</link_name>
      <xDotU>-5.5</xDotU>
      <yDotV>-12.7</yDotV>
      <zDotW>-14.57</zDotW>
      <kDotP>-0.12</kDotP>
      <mDotQ>-0.12</mDotQ>
      <nDotR>-0.12</nDotR>
      <xUabsU>-33.800000000000004</xUabsU>
      <yVabsV>-54.26875</yVabsV>
      <zWabsW>-73.37135</zWabsW>
      <kPabsP>-40.0</kPabsP>
      <mQabsQ>-40.0</mQabsQ>
      <nRabsR>-40.0</nRabsR>
      <xU>-25.15</xU>
      <yV>-7.364</yV>
      <zW>-17.955</zW>
      <kP>-10.888</kP>
      <mQ>-20.761</mQ>
      <nR>-3.744</nR>
    </plugin>
  </gazebo>
  <gazebo>
    <plugin filename="gz-sim-imu-system" name="gz::sim::systems::Imu">
    </plugin>
  </gazebo>
  <link name="bur/imu_link">
    <visual>
      <geometry>
        <box size="0.01 0.01 0.01"/>
      </geometry>
      <material name="green"/>
    </visual>
    <collision>
      <geometry>
        <box size="0.01 0.01 0.01"/>
      </geometry>
    </collision>
  </link>
  <joint name="imu_joint" type="fixed">
    <axis xyz="1 0 0"/>
    <!-- 0 1 0 -->
    <origin xyz="0 0 0.06"/>
    <parent link="bur/base_link"/>
    <child link="bur/imu_link"/>
  </joint>
  <gazebo reference="bur/imu_link">
    <sensor name="imu_sensor" type="imu">
      <always_on>1</always_on>
      <update_rate>1</update_rate>
      <visualize>true</visualize>
      <topic>imu</topic>
    </sensor>
  </gazebo>
  <link name="bur/thruster1">
    <visual>
      <origin rpy="1.5707963267948966 3.141592653589793 0" xyz="0.10 0.10 0"/>
      <geometry>
        <!-- cylinder length="${prop_l}" radius="${prop_r}"/ -->
        <mesh filename="file:///ros2_ws/install/bur_gz/share/bur_gz/meshes/Impeller.STL" scale="0.0007 0.0007 0.0007"/>
      </geometry>
      <material name="yellow"/>
    </visual>
    <collision>
      <origin rpy="1.5707963267948966 3.141592653589793 0" xyz="0.10 0.10 0"/>
      <geometry>
        <!-- cylinder length="${prop_l}" radius="${prop_r}"/ -->
        <mesh filename="file:///ros2_ws/install/bur_gz/share/bur_gz/meshes/Impeller.STL" scale="0.0007 0.0007 0.0007"/>
      </geometry>
    </collision>
    <inertial>
      <!-- thruster axis is X -->
      <origin rpy="0 0 0" xyz="0.0175 0 0"/>
      <mass value="0.07"/>
      <inertia ixx="8.750000000000001e-05" ixy="0.0" ixz="0.0" iyy="5.089583333333334e-05" iyz="0.0" izz="5.089583333333334e-05"/>
    </inertial>
  </link>
  <!-- Joint between thruster link and vehicle base link -->
  <joint name="thruster1" type="continuous">
    <origin rpy="0 0 0" xyz="0.1555 -0.15 -0.0725"/>
    <axis xyz="0 0 1"/>
    <parent link="bur/base_link"/>
    <child link="bur/thruster1"/>
  </joint>
  <!-- ignition topic is /model/{ns}/joint/{joint_name}/cmd_pos -->
  <gazebo>
    <plugin filename="ignition-gazebo-thruster-system" name="ignition::gazebo::systems::Thruster">
      <namespace>bur</namespace>
      <joint_name>thruster1</joint_name>
      <topic>thruster1/cmd</topic>
      <thrust_coefficient>0.011</thrust_coefficient>
      <fluid_density>1000</fluid_density>
      <propeller_diameter>0.1</propeller_diameter>
      <velocity_control>true</velocity_control>
      <use_angvel_cmd>false</use_angvel_cmd>
      <max_thrust_cmd>40</max_thrust_cmd>
      <min_thrust_cmd>-40</min_thrust_cmd>
    </plugin>
  </gazebo>
  <link name="bur/thruster2">
    <visual>
      <origin rpy="1.5707963267948966 3.141592653589793 0" xyz="0.10 0.10 0"/>
      <geometry>
        <!-- cylinder length="${prop_l}" radius="${prop_r}"/ -->
        <mesh filename="file:///ros2_ws/install/bur_gz/share/bur_gz/meshes/Impeller.STL" scale="0.0007 0.0007 0.0007"/>
      </geometry>
      <material name="yellow"/>
    </visual>
    <collision>
      <origin rpy="1.5707963267948966 3.141592653589793 0" xyz="0.10 0.10 0"/>
      <geometry>
        <!-- cylinder length="${prop_l}" radius="${prop_r}"/ -->
        <mesh filename="file:///ros2_ws/install/bur_gz/share/bur_gz/meshes/Impeller.STL" scale="0.0007 0.0007 0.0007"/>
      </geometry>
    </collision>
    <inertial>
      <!-- thruster axis is X -->
      <origin rpy="0 0 0" xyz="0.0175 0 0"/>
      <mass value="0.07"/>
      <inertia ixx="8.750000000000001e-05" ixy="0.0" ixz="0.0" iyy="5.089583333333334e-05" iyz="0.0" izz="5.089583333333334e-05"/>
    </inertial>
  </link>
  <!-- Joint between thruster link and vehicle base link -->
  <joint name="thruster2" type="continuous">
    <origin rpy="0 0 0" xyz="0.1555 0.15 -0.0725"/>
    <axis xyz="0 0 1"/>
    <parent link="bur/base_link"/>
    <child link="bur/thruster2"/>
  </joint>
  <!-- ignition topic is /model/{ns}/joint/{joint_name}/cmd_pos -->
  <gazebo>
    <plugin filename="ignition-gazebo-thruster-system" name="ignition::gazebo::systems::Thruster">
      <namespace>bur</namespace>
      <joint_name>thruster2</joint_name>
      <topic>thruster2/cmd</topic>
      <thrust_coefficient>0.011</thrust_coefficient>
      <fluid_density>1000</fluid_density>
      <propeller_diameter>0.1</propeller_diameter>
      <velocity_control>true</velocity_control>
      <use_angvel_cmd>false</use_angvel_cmd>
      <max_thrust_cmd>40</max_thrust_cmd>
      <min_thrust_cmd>-40</min_thrust_cmd>
    </plugin>
  </gazebo>
  <link name="bur/thruster3">
    <visual>
      <origin rpy="1.5707963267948966 3.141592653589793 0" xyz="0.10 0.10 0"/>
      <geometry>
        <!-- cylinder length="${prop_l}" radius="${prop_r}"/ -->
        <mesh filename="file:///ros2_ws/install/bur_gz/share/bur_gz/meshes/Impeller.STL" scale="0.0007 0.0007 0.0007"/>
      </geometry>
      <material name="yellow"/>
    </visual>
    <collision>
      <origin rpy="1.5707963267948966 3.141592653589793 0" xyz="0.10 0.10 0"/>
      <geometry>
        <!-- cylinder length="${prop_l}" radius="${prop_r}"/ -->
        <mesh filename="file:///ros2_ws/install/bur_gz/share/bur_gz/meshes/Impeller.STL" scale="0.0007 0.0007 0.0007"/>
      </geometry>
    </collision>
    <inertial>
      <!-- thruster axis is X -->
      <origin rpy="0 0 0" xyz="0.0175 0 0"/>
      <mass value="0.07"/>
      <inertia ixx="8.750000000000001e-05" ixy="0.0" ixz="0.0" iyy="5.089583333333334e-05" iyz="0.0" izz="5.089583333333334e-05"/>
    </inertial>
  </link>
  <!-- Joint between thruster link and vehicle base link -->
  <joint name="thruster3" type="continuous">
    <origin rpy="0 0 0" xyz="-0.1555 -0.15 -0.0725"/>
    <axis xyz="0 0 1"/>
    <parent link="bur/base_link"/>
    <child link="bur/thruster3"/>
  </joint>
  <!-- ignition topic is /model/{ns}/joint/{joint_name}/cmd_pos -->
  <gazebo>
    <plugin filename="ignition-gazebo-thruster-system" name="ignition::gazebo::systems::Thruster">
      <namespace>bur</namespace>
      <joint_name>thruster3</joint_name>
      <topic>thruster3/cmd</topic>
      <thrust_coefficient>0.011</thrust_coefficient>
      <fluid_density>1000</fluid_density>
      <propeller_diameter>0.1</propeller_diameter>
      <velocity_control>true</velocity_control>
      <use_angvel_cmd>false</use_angvel_cmd>
      <max_thrust_cmd>40</max_thrust_cmd>
      <min_thrust_cmd>-40</min_thrust_cmd>
    </plugin>
  </gazebo>
  <link name="bur/thruster4">
    <visual>
      <origin rpy="1.5707963267948966 3.141592653589793 0" xyz="0.10 0.10 0"/>
      <geometry>
        <!-- cylinder length="${prop_l}" radius="${prop_r}"/ -->
        <mesh filename="file:///ros2_ws/install/bur_gz/share/bur_gz/meshes/Impeller.STL" scale="0.0007 0.0007 0.0007"/>
      </geometry>
      <material name="yellow"/>
    </visual>
    <collision>
      <origin rpy="1.5707963267948966 3.141592653589793 0" xyz="0.10 0.10 0"/>
      <geometry>
        <!-- cylinder length="${prop_l}" radius="${prop_r}"/ -->
        <mesh filename="file:///ros2_ws/install/bur_gz/share/bur_gz/meshes/Impeller.STL" scale="0.0007 0.0007 0.0007"/>
      </geometry>
    </collision>
    <inertial>
      <!-- thruster axis is X -->
      <origin rpy="0 0 0" xyz="0.0175 0 0"/>
      <mass value="0.07"/>
      <inertia ixx="8.750000000000001e-05" ixy="0.0" ixz="0.0" iyy="5.089583333333334e-05" iyz="0.0" izz="5.089583333333334e-05"/>
    </inertial>
  </link>
  <!-- Joint between thruster link and vehicle base link -->
  <joint name="thruster4" type="continuous">
    <origin rpy="0 0 0" xyz="-0.1555 0.15 -0.0725"/>
    <axis xyz="0 0 1"/>
    <parent link="bur/base_link"/>
    <child link="bur/thruster4"/>
  </joint>
  <!-- ignition topic is /model/{ns}/joint/{joint_name}/cmd_pos -->
  <gazebo>
    <plugin filename="ignition-gazebo-thruster-system" name="ignition::gazebo::systems::Thruster">
      <namespace>bur</namespace>
      <joint_name>thruster4</joint_name>
      <topic>thruster4/cmd</topic>
      <thrust_coefficient>0.011</thrust_coefficient>
      <fluid_density>1000</fluid_density>
      <propeller_diameter>0.1</propeller_diameter>
      <velocity_control>true</velocity_control>
      <use_angvel_cmd>false</use_angvel_cmd>
      <max_thrust_cmd>40</max_thrust_cmd>
      <min_thrust_cmd>-40</min_thrust_cmd>
    </plugin>
  </gazebo>
  <link name="bur/thruster5">
    <visual>
      <origin rpy="1.5707963267948966 3.141592653589793 0" xyz="0.10 0.10 0"/>
      <geometry>
        <!-- cylinder length="${prop_l}" radius="${prop_r}"/ -->
        <mesh filename="file:///ros2_ws/install/bur_gz/share/bur_gz/meshes/Impeller.STL" scale="0.0007 0.0007 0.0007"/>
      </geometry>
      <material name="red"/>
    </visual>
    <collision>
      <origin rpy="1.5707963267948966 3.141592653589793 0" xyz="0.10 0.10 0"/>
      <geometry>
        <!-- cylinder length="${prop_l}" radius="${prop_r}"/ -->
        <mesh filename="file:///ros2_ws/install/bur_gz/share/bur_gz/meshes/Impeller.STL" scale="0.0007 0.0007 0.0007"/>
      </geometry>
    </collision>
    <inertial>
      <!-- thruster axis is X -->
      <origin rpy="0 0 0" xyz="0.0175 0 0"/>
      <mass value="0.07"/>
      <inertia ixx="8.750000000000001e-05" ixy="0.0" ixz="0.0" iyy="5.089583333333334e-05" iyz="0.0" izz="5.089583333333334e-05"/>
    </inertial>
  </link>
  <!-- Joint between thruster link and vehicle base link -->
  <joint name="thruster5" type="continuous">
    <origin rpy="-0.7853981633974483 1.5707963267948966 0" xyz="0.13333333333333333 -0.26666666666666666 0"/>
    <axis xyz="0 0 1"/>
    <parent link="bur/base_link"/>
    <child link="bur/thruster5"/>
  </joint>
  <!-- ignition topic is /model/{ns}/joint/{joint_name}/cmd_pos -->
  <gazebo>
    <plugin filename="ignition-gazebo-thruster-system" name="ignition::gazebo::systems::Thruster">
      <namespace>bur</namespace>
      <joint_name>thruster5</joint_name>
      <topic>thruster5/cmd</topic>
      <thrust_coefficient>0.011</thrust_coefficient>
      <fluid_density>1000</fluid_density>
      <propeller_diameter>0.1</propeller_diameter>
      <velocity_control>true</velocity_control>
      <use_angvel_cmd>false</use_angvel_cmd>
      <max_thrust_cmd>40</max_thrust_cmd>
      <min_thrust_cmd>-40</min_thrust_cmd>
    </plugin>
  </gazebo>
  <link name="bur/thruster6">
    <visual>
      <origin rpy="1.5707963267948966 3.141592653589793 0" xyz="0.10 0.10 0"/>
      <geometry>
        <!-- cylinder length="${prop_l}" radius="${prop_r}"/ -->
        <mesh filename="file:///ros2_ws/install/bur_gz/share/bur_gz/meshes/Impeller.STL" scale="0.0007 0.0007 0.0007"/>
      </geometry>
      <material name="red"/>
    </visual>
    <collision>
      <origin rpy="1.5707963267948966 3.141592653589793 0" xyz="0.10 0.10 0"/>
      <geometry>
        <!-- cylinder length="${prop_l}" radius="${prop_r}"/ -->
        <mesh filename="file:///ros2_ws/install/bur_gz/share/bur_gz/meshes/Impeller.STL" scale="0.0007 0.0007 0.0007"/>
      </geometry>
    </collision>
    <inertial>
      <!-- thruster axis is X -->
      <origin rpy="0 0 0" xyz="0.0175 0 0"/>
      <mass value="0.07"/>
      <inertia ixx="8.750000000000001e-05" ixy="0.0" ixz="0.0" iyy="5.089583333333334e-05" iyz="0.0" izz="5.089583333333334e-05"/>
    </inertial>
  </link>
  <!-- Joint between thruster link and vehicle base link -->
  <joint name="thruster6" type="continuous">
    <origin rpy="0.7853981633974483 1.5707963267948966 0" xyz="0.13333333333333333 0.26666666666666666 0"/>
    <axis xyz="0 0 1"/>
    <parent link="bur/base_link"/>
    <child link="bur/thruster6"/>
  </joint>
  <!-- ignition topic is /model/{ns}/joint/{joint_name}/cmd_pos -->
  <gazebo>
    <plugin filename="ignition-gazebo-thruster-system" name="ignition::gazebo::systems::Thruster">
      <namespace>bur</namespace>
      <joint_name>thruster6</joint_name>
      <topic>thruster6/cmd</topic>
      <thrust_coefficient>0.011</thrust_coefficient>
      <fluid_density>1000</fluid_density>
      <propeller_diameter>0.1</propeller_diameter>
      <velocity_control>true</velocity_control>
      <use_angvel_cmd>false</use_angvel_cmd>
      <max_thrust_cmd>40</max_thrust_cmd>
      <min_thrust_cmd>-40</min_thrust_cmd>
    </plugin>
  </gazebo>
  <link name="bur/thruster7">
    <visual>
      <origin rpy="1.5707963267948966 3.141592653589793 0" xyz="0.10 0.10 0"/>
      <geometry>
        <!-- cylinder length="${prop_l}" radius="${prop_r}"/ -->
        <mesh filename="file:///ros2_ws/install/bur_gz/share/bur_gz/meshes/Impeller.STL" scale="0.0007 0.0007 0.0007"/>
      </geometry>
      <material name="red"/>
    </visual>
    <collision>
      <origin rpy="1.5707963267948966 3.141592653589793 0" xyz="0.10 0.10 0"/>
      <geometry>
        <!-- cylinder length="${prop_l}" radius="${prop_r}"/ -->
        <mesh filename="file:///ros2_ws/install/bur_gz/share/bur_gz/meshes/Impeller.STL" scale="0.0007 0.0007 0.0007"/>
      </geometry>
    </collision>
    <inertial>
      <!-- thruster axis is X -->
      <origin rpy="0 0 0" xyz="0.0175 0 0"/>
      <mass value="0.07"/>
      <inertia ixx="8.750000000000001e-05" ixy="0.0" ixz="0.0" iyy="5.089583333333334e-05" iyz="0.0" izz="5.089583333333334e-05"/>
    </inertial>
  </link>
  <!-- Joint between thruster link and vehicle base link -->
  <joint name="thruster7" type="continuous">
    <origin rpy="-0.7853981633974483 -1.5707963267948966 0" xyz="-0.13333333333333333 -0.26666666666666666 0"/>
    <axis xyz="0 0 1"/>
    <parent link="bur/base_link"/>
    <child link="bur/thruster7"/>
  </joint>
  <!-- ignition topic is /model/{ns}/joint/{joint_name}/cmd_pos -->
  <gazebo>
    <plugin filename="ignition-gazebo-thruster-system" name="ignition::gazebo::systems::Thruster">
      <namespace>bur</namespace>
      <joint_name>thruster7</joint_name>
      <topic>thruster7/cmd</topic>
      <thrust_coefficient>0.011</thrust_coefficient>
      <fluid_density>1000</fluid_density>
      <propeller_diameter>0.1</propeller_diameter>
      <velocity_control>true</velocity_control>
      <use_angvel_cmd>false</use_angvel_cmd>
      <max_thrust_cmd>40</max_thrust_cmd>
      <min_thrust_cmd>-40</min_thrust_cmd>
    </plugin>
  </gazebo>
  <link name="bur/thruster8">
    <visual>
      <origin rpy="1.5707963267948966 3.141592653589793 0" xyz="0.10 0.10 0"/>
      <geometry>
        <!-- cylinder length="${prop_l}" radius="${prop_r}"/ -->
        <mesh filename="file:///ros2_ws/install/bur_gz/share/bur_gz/meshes/Impeller.STL" scale="0.0007 0.0007 0.0007"/>
      </geometry>
      <material name="red"/>
    </visual>
    <collision>
      <origin rpy="1.5707963267948966 3.141592653589793 0" xyz="0.10 0.10 0"/>
      <geometry>
        <!-- cylinder length="${prop_l}" radius="${prop_r}"/ -->
        <mesh filename="file:///ros2_ws/install/bur_gz/share/bur_gz/meshes/Impeller.STL" scale="0.0007 0.0007 0.0007"/>
      </geometry>
    </collision>
    <inertial>
      <!-- thruster axis is X -->
      <origin rpy="0 0 0" xyz="0.0175 0 0"/>
      <mass value="0.07"/>
      <inertia ixx="8.750000000000001e-05" ixy="0.0" ixz="0.0" iyy="5.089583333333334e-05" iyz="0.0" izz="5.089583333333334e-05"/>
    </inertial>
  </link>
  <!-- Joint between thruster link and vehicle base link -->
  <joint name="thruster8" type="continuous">
    <origin rpy="0.7853981633974483 -1.5707963267948966 0" xyz="-0.13333333333333333 0.26666666666666666 0"/>
    <axis xyz="0 0 1"/>
    <parent link="bur/base_link"/>
    <child link="bur/thruster8"/>
  </joint>
  <!-- ignition topic is /model/{ns}/joint/{joint_name}/cmd_pos -->
  <gazebo>
    <plugin filename="ignition-gazebo-thruster-system" name="ignition::gazebo::systems::Thruster">
      <namespace>bur</namespace>
      <joint_name>thruster8</joint_name>
      <topic>thruster8/cmd</topic>
      <thrust_coefficient>0.011</thrust_coefficient>
      <fluid_density>1000</fluid_density>
      <propeller_diameter>0.1</propeller_diameter>
      <velocity_control>true</velocity_control>
      <use_angvel_cmd>false</use_angvel_cmd>
      <max_thrust_cmd>40</max_thrust_cmd>
      <min_thrust_cmd>-40</min_thrust_cmd>
    </plugin>
  </gazebo>
  <link name="bur/camera1_link">
    <inertial>
      <mass value="0.10"/>
      <inertia ixx="0.000166667" ixy="1" ixz="1" iyy="0.000166667" iyz="1" izz="0.000166667"/>
    </inertial>
    <collision>
      <geometry>
        <box size="0.01 0.01 0.01"/>
      </geometry>
    </collision>
    <visual>
      <geometry>
        <box size="0.01 0.01 0.01"/>
      </geometry>
    </visual>
  </link>
  <joint name="bur/camera1_joint" type="fixed">
    <origin rpy="0 0 0" xyz="0.1 0 0.06"/>
    <parent link="bur/base_link"/>
    <child link="bur/camera1_link"/>
  </joint>
  <gazebo reference="bur/camera1_link">
    <material>Gazebo/Green</material>
    <sensor name="camera" type="camera">
      <camera>
        <horizontal_fov>1.047</horizontal_fov>
        <image>
          <width>320</width>
          <height>240</height>
        </image>
        <clip>
          <near>0.1</near>
          <far>100</far>
        </clip>
      </camera>
      <always_on>1</always_on>
      <update_rate>30</update_rate>
      <visualize>true</visualize>
      <topic>camera</topic>
    </sensor>
  </gazebo>
  <gazebo>
    <plugin filename="ignition-gazebo-joint-state-publisher-system" name="ignition::gazebo::systems::JointStatePublisher"/>
    <plugin filename="ignition-gazebo-odometry-publisher-system" name="ignition::gazebo::systems::OdometryPublisher">
      <odom_frame>bur/odom</odom_frame>
      <dimensions>3</dimensions>
      <robot_base_frame>bur/dlink</robot_base_frame>
      <odom_publish_frequency>10</odom_publish_frequency>
    </plugin>
    <plugin filename="libgazebo_ros_p3d.so" name="gazebo_ros_p3d">
      <ros>
        <!-- Use your desired namespace or leave empty for default -->
        <namespace>/your_robot_namespace</namespace>
        <!-- The topic name where the position will be published -->
        <remapping>odom:=/odom</remapping>
      </ros>
      <!-- Replace with your robot's main link -->
      <body_name>base_link</body_name>
      <!-- Update rate in Hz -->
      <update_rate>30.0</update_rate>
      <xyzOffsets>0 0 0</xyzOffsets>
      <rpyOffsets>0 0 0</rpyOffsets>
    </plugin>
    <plugin filename="ignition-gazebo-pose-publisher-system" name="ignition::gazebo::systems::PosePublisher">
      <publish_link_pose>false</publish_link_pose>
      <publish_collision_pose>false</publish_collision_pose>
      <publish_visual_pose>false</publish_visual_pose>
      <publish_nested_model_pose>true</publish_nested_model_pose>
    </plugin>
  </gazebo>
</robot>
